Workbook

Sheet Aneen's copy
B1: Forecasted Volume
B2: ISS Calls | C2: ISS Emails | D2: NSC Calls | E2: NSC Emails | F2: NSC Livechat | G2: Weeks | I2: Phone | J2: Email | K2: Livechat
A3: January | B3: 15505 | C3: 9698 | D3: 6464 | E3: 15092 | F3: 2980 | G3: 5 | I3: =SUM(B3,D3)/G3 -> 4393.8 | J3: =SUM(C3,E3)/G3 -> 4958 | K3: =F3/G3 -> 596
A4: February | B4: 16674 | C4: 10116 | D4: 7889 | E4: 12383 | F4: 2900 | G4: 4 | I4: =SUM(B4,D4)/G4 -> 6140.75 | J4: =SUM(C4,E4)/G4 -> 5624.75 | K4: =F4/G4 -> 725
A5: March | B5: 21085 | C5: 12225 | D5: 9269 | E5: 17597 | F5: 3802 | G5: 5 | I5: =SUM(B5,D5)/G5 -> 6070.8 | J5: =SUM(C5,E5)/G5 -> 5964.4 | K5: =F5/G5 -> 760.4
A6: April | B6: 14799 | C6: 10052 | D6: 7219 | E6: 13774 | F6: 2727 | G6: 4 | I6: =SUM(B6,D6)/G6 -> 5504.5 | J6: =SUM(C6,E6)/G6 -> 5956.5 | K6: =F6/G6 -> 681.75
A7: May | B7: 14296 | C7: 9834 | D7: 5825 | E7: 15146 | F7: 2754 | G7: 4 | I7: =SUM(B7,D7)/G7 -> 5030.25 | J7: =SUM(C7,E7)/G7 -> 6245 | K7: =F7/G7 -> 688.5
A8: June | B8: 17108 | C8: 12169 | D8: 7532 | E8: 17985 | F8: 3874 | G8: 5 | I8: =SUM(B8,D8)/G8 -> 4928 | J8: =SUM(C8,E8)/G8 -> 6030.8 | K8: =F8/G8 -> 774.8
A9: July | B9: 11068 | C9: 9297 | D9: 4741 | E9: 14905 | F9: 2898 | G9: 4 | I9: =SUM(B9,D9)/G9 -> 3952.25 | J9: =SUM(C9,E9)/G9 -> 6050.5 | K9: =F9/G9 -> 724.5
A10: August | B10: 13896 | C10: 10515 | D10: 5978 | E10: 19566 | F10: 2469 | G10: 4 | I10: =SUM(B10,D10)/G10 -> 4968.5 | J10: =SUM(C10,E10)/G10 -> 7520.25 | K10: =F10/G10 -> 617.25
A11: September | B11: 19253 | C11: 14345 | D11: 8578 | E11: 25070 | F11: 3720 | G11: 5 | I11: =SUM(B11,D11)/G11 -> 5566.2 | J11: =SUM(C11,E11)/G11 -> 7883 | K11: =F11/G11 -> 744
A12: October | B12: 16476 | C12: 11607 | D12: 7494 | E12: 22052 | F12: 3220 | G12: 4 | I12: =SUM(B12,D12)/G12 -> 5992.5 | J12: =SUM(C12,E12)/G12 -> 8414.75 | K12: =F12/G12 -> 805
A13: November | B13: 16900 | C13: 11812 | D13: 7628 | E13: 22679 | F13: 3622 | G13: 4 | I13: =SUM(B13,D13)/G13 -> 6132 | J13: =SUM(C13,E13)/G13 -> 8622.75 | K13: =F13/G13 -> 905.5
A14: December | B14: 16244 | C14: 11858 | D14: 8597 | E14: 21031 | F14: 3243 | G14: 5 | I14: =SUM(B14,D14)/G14 -> 4968.2 | J14: =SUM(C14,E14)/G14 -> 6577.8 | K14: =F14/G14 -> 648.6

Sheet Outbound
B2: Phone - Outbound
B3: Scheduled Calls | C3: =E3 -> 681 | E3: =23+47+61+55+78+73+74+77+91+102 -> 681 | F3: computation from Curlyn's email OB Giders
B4: Total Orders | C4: 207 | E4: updated by SAP files thru power bi
B5: Strike Rate | C5: =C4/C3 -> 0.30396476 | E5: get from pbi
B6: Total FTE | C6: 4 | E6: get from pbi
B7: Average Calls | C7: 19 | E7: get from pbi
B11: Manually update from pbi

Sheet Sheet2
B3: Australia | C3: Phone | E3: Livechat | G3: Email
B4: Customer Satisfaction | D4: 4.6 | F4: NA | H4: NA
B5: Net Promoter Score | D5: 0.5 | F5: NA | H5: NA
B6: Service Level | C6: =D6 -> 0.87975035 | D6: ='Power BI'!C26 -> 0.87975035 | E6: =F6 -> 0.94378194 | F6: ='Power BI'!R21 -> 0.94378194 | G6: =H6 -> 0.82 | H6: 0.82 | J6: get email SL from power bi
B7: ASA | C7: =D7 -> 13 | D7: 13 | E7: =F7 -> 9 | F7: 9 | H7: NA | J7: get asa from genesys directly
B8: Abandoned | C8: =D8 -> 0.025 | D8: ='Power BI'!E26 -> 0.025 | F8: NA | H8: NA
B9: Volume | D9: ='Power BI'!F26 -> 5773 | F9: ='Power BI'!U21 -> 592 | H9: 4904 | J9: get email volume from power bi
B10: Volume vs FCST | C10: =ABS(D10) -> 0.048778272 | D10: =(D9-C33)/C33 -> 0.048778272 | E10: =ABS(F10) -> 0.1316465 | F10: =(F9-E33)/E33 -> -0.1316465 | G10: =ABS(H10) -> 0.17669773 | H10: =(H9-D33)/D33 -> -0.17669773
B11: Average Handle Time | D11: 7m 24s | F11: 12m 38s | H11: NA | J11: manually update this
B12: AHT vs LY | C12: =D12 -> 0.034965035 | D12: =((LEFT(D11,FIND("m",D11)-1)*60+MID(D11,FIND(" ",D11)+1,FIND("s",D11)-FIND(" ",D11)-1))-(LEFT(H30,FIND("m",H30)-1)*60+MID(H30,FIND(" ",H30)+1,FIND("s",H30)-FIND(" ",H30)-1)))/(LEFT(H30,FIND("m",H30)-1)*60+MID(H30,FIND(" ",H30)+1,FIND("s",H30)-FIND(" ",H30)-1)) -> 0.034965035 | E12: =F12 -> 0.069111425 | F12: =((LEFT(F11,FIND("m",F11)-1)*60+MID(F11,FIND(" ",F11)+1,FIND("s",F11)-FIND(" ",F11)-1))-(LEFT(J30,FIND("m",J30)-1)*60+MID(J30,FIND(" ",J30)+1,FIND("s",J30)-FIND(" ",J30)-1)))/(LEFT(J30,FIND("m",J30)-1)*60+MID(J30,FIND(" ",J30)+1,FIND("s",J30)-FIND(" ",J30)-1)) -> 0.069111425 | H12: NA
B13: AHT vs FCST | C13: =D13 -> -0.096557121 | D13: =(D9-K29)/K29 -> -0.096557121 | E13: =F13 -> -0.013333333 | F13: =(F9-M29)/M29 -> -0.013333333 | H13: NA
B14: FTE vs FCST | C14: =ABS(D14) -> 0.14 | D14: 0.14 | F14: NA | H14: NA | J14: fte vs forecast manual update from aneens copy and number of agents from genesys
B15: Adherence | C15: =D15 -> 0.94 | D15: 0.94 | F15: NA | H15: NA | J15: get from power bi
B16: Shrinkage | C16: =D16 -> 0.23 | D16: 0.23 | F16: NA | H16: NA | J16: get from powr bi
B21: Note:
B22: Forecast Colour‑Coding Rationale: Variances within ±5% are considered on target. Results that exceed ±10% will be flagged as Amber, and results with substantial deviation beyond this range will be flagged as Red.
B25: Change the reference depending on the week reported | H25: Get update from genesys everyday
B26: Forecast numbers | H26: LY Data | K26: AHT FCST
C28: Phone | D28: email | E28: livechat | H28: Phone | I28: email | J28: livechat | K28: Phone | M28: Live Chat
K29: =SUM(B49:H49,J49:Q49) -> 6390 | M29: =I49 -> 600
B30: January | C30: ='Aneen''s copy'!I3 -> 4393.8 | D30: ='Aneen''s copy'!J3 -> 4958 | E30: ='Aneen''s copy'!K3 -> 596 | H30: 7m 9s | J30: 11m 49s
B31: February | C31: ='Aneen''s copy'!I4 -> 6140.75 | D31: ='Aneen''s copy'!J4 -> 5624.75 | E31: ='Aneen''s copy'!K4 -> 725
B32: March | C32: ='Aneen''s copy'!I5 -> 6070.8 | D32: ='Aneen''s copy'!J5 -> 5964.4 | E32: ='Aneen''s copy'!K5 -> 760.4
B33: April | C33: ='Aneen''s copy'!I6 -> 5504.5 | D33: ='Aneen''s copy'!J6 -> 5956.5 | E33: ='Aneen''s copy'!K6 -> 681.75
B34: May | C34: ='Aneen''s copy'!I7 -> 5030.25 | D34: ='Aneen''s copy'!J7 -> 6245 | E34: ='Aneen''s copy'!K7 -> 688.5
B35: June | C35: ='Aneen''s copy'!I8 -> 4928 | D35: ='Aneen''s copy'!J8 -> 6030.8 | E35: ='Aneen''s copy'!K8 -> 774.8
B36: July | C36: ='Aneen''s copy'!I9 -> 3952.25 | D36: ='Aneen''s copy'!J9 -> 6050.5 | E36: ='Aneen''s copy'!K9 -> 724.5
B37: August | C37: ='Aneen''s copy'!I10 -> 4968.5 | D37: ='Aneen''s copy'!J10 -> 7520.25 | E37: ='Aneen''s copy'!K10 -> 617.25
B38: September | C38: ='Aneen''s copy'!I11 -> 5566.2 | D38: ='Aneen''s copy'!J11 -> 7883 | E38: ='Aneen''s copy'!K11 -> 744
B39: October | C39: ='Aneen''s copy'!I12 -> 5992.5 | D39: ='Aneen''s copy'!J12 -> 8414.75 | E39: ='Aneen''s copy'!K12 -> 805
B40: November | C40: ='Aneen''s copy'!I13 -> 6132 | D40: ='Aneen''s copy'!J13 -> 8622.75 | E40: ='Aneen''s copy'!K13 -> 905.5
B41: December | C41: ='Aneen''s copy'!I14 -> 4968.2 | D41: ='Aneen''s copy'!J14 -> 6577.8 | E41: ='Aneen''s copy'!K14 -> 648.6
B44: Update if needed from Aneen's copy
B45: AHT FCST
B48: Sales | C48: New Business | D48: myCCA | E48: Grinders_Caffitaly_AU | F48: Grinders_Rep_AU | G48: Grinders_Sales_AU | H48: Grinders_Tech_AU | I48: Live Chat | J48: Consumer | K48: Tech | L48: Vending | M48: Delivery | N48: Delivery 2 | O48: Credit Enquiries_2_AU | P48: Credit | Q48: EQS
B49: 420 | C49: 600 | D49: 320 | E49: 380 | F49: 600 | G49: 420 | H49: 380 | I49: 600 | J49: 390 | K49: 330 | L49: 390 | M49: 420 | N49: 420 | O49: 510 | P49: 510 | Q49: 300

Sheet Working File
C2: Phone - Inbound | E2: SLA | G2: ASA | I2: Abandoned | K2: Volume vs FCST | N2: AHT vs FCST | Q2: Owner | R2: Queues | X2: Column Labels
C3: Services | W3: Day | X3: NSC_Allocators_PG | Y3: NSC_ConsumerRelations_PG | Z3: NSC_CreditEnquiries_2_PG | AA3: NSC_CreditEnquiries_PG | AB3: NSC_Delivery_2_PG | AC3: NSC_Delivery_PG | AD3: NSC_LiveAgent_PG | AE3: NSC_myCCA_PG | AF3: NSC_Tech_PG | AG3: NSC_Vending_PG | AH3: Grand Total
C4: Equipment | D4: =AB34 -> 0.83799405 | E4: =AB34 -> 0.83799405 | F4: =AC34 -> 19 | G4: =AC34&"s" -> 19s | H4: =I4 -> 0.046 | I4: =AD34 -> 0.046 | J4: =Y47 -> 0.18671434 | K4: =J4 -> 0.18671434 | L4: =Y47 -> 0.18671434 | M4: =Y34 -> 1816 | N4: =AA47 -> 0.22352941 | O4: =AA47 -> 0.22352941 | P4: =AI34 -> 6m 56s | Q4: ISS | R4: Tech_AU, Vending_AU, EQS Allocators_AU | W4: Monday | X4: 3.9533451 | Y4: 54.365461 | Z4: 51.111345 | AA4: 102.10043 | AB4: 53.21194 | AC4: 226.66197 | AD4: 121.79202 | AE4: 23.900315 | AF4: 169.89482 | AG4: 130.2818 | AH4: 937.27345
C5: Delivery | D5: =AB35 -> 0.88415373 | E5: =AB35 -> 0.88415373 | F5: =AC35 -> 11 | G5: =AC35&"s" -> 11s | H5: =I5 -> 0.03 | I5: =AD35 -> 0.03 | J5: =Y48 -> 0.046903526 | K5: =J5 -> 0.046903526 | L5: =Y48 -> 0.046903526 | M5: =Y35 -> 1233 | N5: =AA48 -> 0.23809524 | O5: =AA48 -> 0.23809524 | P5: =AI35 -> 8m 40s | Q5: AU | R5: Delivery_AU, Delivery 2_AU | W5: Tuesday | X5: 3.9537504 | Y5: 47.893581 | Z5: 40.888887 | AA5: 86.257258 | AB5: 66.515118 | AC5: 218.14861 | AD5: 109.74224 | AE5: 20.22345 | AF5: 159.59275 | AG5: 141.9382 | AH5: 895.15385
C6: Credit | D6: =AB36 -> 0.89605796 | E6: =AB36 -> 0.89605796 | F6: =AC36 -> 14 | G6: =AC36&"s" -> 14s | H6: =I6 -> 0.011 | I6: =AD36 -> 0.011 | J6: =Y49 -> 0.87346335 | K6: =J6 -> 0.87346335 | L6: =Y49 -> 0.87346335 | M6: =Y36 -> 978 | N6: =AA49 -> -0.23529412 | O6: =AA49 -> -0.23529412 | P6: =AI36 -> 6m 30s | Q6: ISS | R6: Credit Enquiries_AU, Credit Enquiries_2_AU | W6: Wednesday | X6: 3.953264 | Y6: 50.482106 | Z6: 36.629292 | AA6: 84.555578 | AB6: 61.963978 | AC6: 212.82728 | AD6: 108.02028 | AE6: 20.590794 | AF6: 151.388 | AG6: 140.56619 | AH6: 870.97676
C7: myCCA | D7: =AB37 -> 0.80650339 | E7: =AB37 -> 0.80650339 | F7: =AC37 -> 18 | G7: =AC37&"s" -> 18s | H7: =I7 -> 0.034 | I7: =AD37 -> 0.034 | J7: =Y50 -> 1.0270552 | K7: =J7 -> 1.0270552 | L7: =Y50 -> 1.0270552 | M7: =Y37 -> 180 | N7: =AA50 -> 0.309375 | O7: =AA50 -> 0.309375 | P7: =AI37 -> 6m 59s | Q7: AU | R7: myCCA_AU | W7: Thursday | X7: 4.3490201 | Y7: 47.893581 | Z7: 40.037062 | AA7: 80.271928 | AB7: 61.613814 | AC7: 215.48832 | AD7: 101.99573 | AE7: 16.914293 | AF7: 150.6476 | AG7: 138.50995 | AH7: 857.72129
C8: Consumer | D8: =AB38 -> 0.96113074 | E8: =AB38 -> 0.96113074 | F8: =AC38 -> 5 | G8: =AC38&"s" -> 5s | H8: =I8 -> 0.008 | I8: =AD38 -> 0.008 | J8: =Y51 -> 0.4105235 | K8: =J8 -> 0.4105235 | L8: =Y51 -> 0.4105235 | M8: =Y38 -> 283 | N8: =AA51 -> 0.041025641 | O8: =AA51 -> 0.041025641 | P8: =AI38 -> 6m 46s | Q8: AU | R8: Consumer Services_AU | W8: Friday | X8: 3.1628868 | Y8: 54.365272 | Z8: 38.333414 | AA8: 74.638758 | AB8: 51.111568 | AC8: 226.12948 | AD8: 92.097753 | AE8: 18.201236 | AF8: 141.39423 | AG8: 126.16728 | AH8: 825.60188
C9: Sales | W9: Saturday | X9: 7.9066902 | AA9: 0.05868112 | AB9: 0.23349418 | AC9: 35.205669 | AD9: 22.378638 | AE9: 3.4930474 | AF9: 90.313904 | AG9: 82.282758 | AH9: 241.87288
C10: Sales | D10: =AB39 -> 0.92167834 | E10: =AB39 -> 0.92167834 | F10: =AC39 -> 14 | G10: =AC39&"s" -> 14s | H10: =I10 -> 0.004 | I10: =AD39 -> 0.004 | J10: =Y52 -> 0.42687026 | K10: =J10 -> 0.42687026 | L10: =Y52 -> 0.42687026 | M10: =Y39 -> 1137 | N10: =AA52 -> 0.016666667 | O10: =AA52 -> 0.016666667 | P10: =AI39 -> 7m 07s | Q10: ISS | R10: Sales AU | W10: Sunday | X10: 6.7210433 | AA10: 0.11736224 | AB10: 0.35008765 | AC10: 25.538663 | AD10: 27.97334 | AE10: 3.6768652 | AF10: 74.768693 | AG10: 69.253827 | AH10: 208.39988
C11: New Business | D11: =AB40 -> 0.85135135 | E11: =AB40 -> 0.85135135 | F11: =AC40 -> 15 | G11: =AC40&"s" -> 15s | H11: =I11 -> 0.028 | I11: =AD40 -> 0.028 | J11: =Y53 -> 0.18097673 | K11: =J11 -> 0.18097673 | L11: =Y53 -> 0.18097673 | M11: =Y40 -> 74 | N11: =AA53 -> 0.585 | O11: =AA53 -> 0.585 | P11: =AI40 -> 15m 51s | Q11: ISS | R11: New_Business_AU | X11: 34 | Y11: 255 | Z11: 207 | AA11: 428 | AB11: 295 | AC11: 1160 | AD11: 584 | AE11: 107 | AF11: 938 | AG11: 829 | AH11: 4837
C12: Grinders | D12: =AB41 -> 0.86111111 | E12: =AB41 -> 0.86111111 | F12: =AC41 -> 21 | G12: =AC41&"s" -> 21s | H12: =I12 -> 0.014 | I12: =AD41 -> 0.014 | J12: =Y54 -> 0.35662865 | K12: =J12 -> 0.35662865 | L12: =Y54 -> 0.35662865 | M12: =Y41 -> 72 | N12: =AA54 -> -0.026966292 | O12: =AA54 -> -0.026966292 | P12: =AI41 -> 7m 13s | Q12: ISS & AU | R12: Sales_AU, Tech_AU, Rep_AU, Credits_AU, Caffitaly_AU
W13: Day | X13: NSC_Email_Consumer_PG | Y13: NSC_Email_DigitalSupport_PG | Z13: NSC_Email_Inbound_Credit_PG | AA13: NSC_Email_Online_EQS_PG | AB13: NSC_Email_Order&Delivery_PG | AC13: NSC_Email_OrderMaintenance_PG | AD13: Grand Total
W14: Monday | X14: 136.51264 | Y14: 50.570381 | Z14: 228.39376 | AA14: 46.811317 | AB14: 24.506059 | AC14: 50.368064 | AD14: 537.16221
W15: Tuesday | X15: 156.88915 | Y15: 39.507094 | Z15: 166.52873 | AA15: 43.854763 | AB15: 24.506059 | AC15: 57.774478 | AD15: 489.06028
W16: Wednesday | X16: 179.30102 | Y16: 42.668328 | Z16: 157.96868 | AA16: 38.927382 | AB16: 32.677868 | AC16: 60.738683 | AD16: 512.28196
W17: Thursday | X17: 167.0739 | Y17: 42.66801 | Z17: 153.68919 | AA17: 37.449778 | AB17: 46.293733 | AC17: 59.25658 | AD17: 506.43119
W18: Friday | X18: 132.4381 | Y18: 38.19064 | Z18: 143.57243 | AA18: 41.883831 | AB18: 49.016281 | AC18: 50.368649 | AD18: 455.46992
W19: Saturday | X19: 107.98673 | Y19: 15.802045 | Z19: 8.1709608 | AA19: 14.29037 | AC19: 0.49354625 | AD19: 146.74365
W20: Sunday | X20: 97.798471 | Y20: 16.593503 | Z20: 18.676248 | AA20: 14.782559 | AD20: 147.85078
X21: 978 | Y21: 246 | Z21: 877 | AA21: 238 | AB21: 177 | AC21: 279 | AD21: 2795
W23: Day | X23: AU_Grinders_PG | Y23: NSC_NewBusiness_PG | Z23: NSC_Sales_PG | AA23: Grand Total
W24: Monday | X24: 14.788205 | Y24: 18.31809 | Z24: 240.21314 | AA24: 273.31943
W25: Tuesday | X25: 12.323323 | Y25: 16.42836 | Z25: 193.94057 | AA25: 222.69226
W26: Wednesday | X26: 10.679974 | Y26: 13.956774 | Z26: 166.61646 | AA26: 191.25321
W27: Thursday | X27: 11.501848 | Y27: 13.956774 | Z27: 167.86426 | AA27: 193.32288
W28: Friday | X28: 9.9272596 | Y28: 11.340001 | Z28: 167.1511 | AA28: 188.41836
W29: Saturday | X29: 2.1360975 | Z29: 13.186306 | AA29: 15.322403
W30: Sunday | X30: 1.6432925 | Z30: 15.028169 | AA30: 16.671461
X31: 63 | Y31: 74 | Z31: 964 | AA31: 1101
W33: FCST Volume | X33: Forecasted Volume | Y33: Actual Volume | Z33: Forecasted AHT | AA33: Actual AHT | AB33: SL | AC33: ASA | AD33: Abandoned No Short % | AE33: Offer | AF33: Answered | AG33: AHT | AH33: Avg Wait
W34: Equipment | X34: =SUM(X4:X7,X9:X10,AF4:AF7,AF9:AF10,AG4:AG7,AG9:AG10) -> 1530.2756 | Y34: =AE34 -> 1816 | Z34: =SUM(Sheet2!K49,Sheet2!L49,Sheet2!Q49)/3 -> 340 | AA34: =AG34 -> 416 | AB34: ='Power BI'!C2 -> 0.83799405 | AC34: =TIMEVALUE('Power BI'!D2)*86400 -> 19 | AD34: ='Power BI'!E2 -> 0.046 | AE34: ='Power BI'!F2 -> 1816 | AF34: ='Power BI'!G2 -> 1725 | AG34: =TIMEVALUE('Power BI'!H2) * 86400 -> 416 | AH34: =TIMEVALUE('Power BI'!I2)*86400 -> 26 | AI34: =INT(AG34/60) & "m" & IF(MOD(AG34,60)=0,""," " & TEXT(MOD(AG34,60),"00") & "s") -> 6m 56s
W35: Delivery | X35: =SUM(AB4:AB7,AB9:AB10,AC4:AC7,AC9:AC10) -> 1177.759 | Y35: =AE35 -> 1233 | Z35: =SUM(Sheet2!M49,Sheet2!N49)/2 -> 420 | AA35: =AG35 -> 520 | AB35: ='Power BI'!C6 -> 0.88415373 | AC35: =TIMEVALUE('Power BI'!D6)*86400 -> 11 | AD35: ='Power BI'!E6 -> 0.03 | AE35: ='Power BI'!F6 -> 1233 | AF35: ='Power BI'!G6 -> 1194 | AG35: =TIMEVALUE('Power BI'!H6)*86400 -> 520 | AH35: =TIMEVALUE('Power BI'!I6)*86400 -> 17 | AI35: =INT(AG35/60) & "m" & IF(MOD(AG35,60)=0,""," " & TEXT(MOD(AG35,60),"00") & "s") -> 8m 40s
W36: Credit | X36: =SUM(AA4:AA7,AA9:AA10,Z4:Z7,Z9:Z10) -> 522.02783 | Y36: =AE36 -> 978 | Z36: =SUM(Sheet2!O49,Sheet2!P49)/2 -> 510 | AA36: =AG36 -> 390 | AB36: ='Power BI'!C9 -> 0.89605796 | AC36: =TIMEVALUE('Power BI'!D9)*86400 -> 14 | AD36: ='Power BI'!E9 -> 0.011 | AE36: ='Power BI'!F9 -> 978 | AF36: ='Power BI'!G9 -> 965 | AG36: =TIMEVALUE('Power BI'!H9)*86400 -> 390 | AH36: =TIMEVALUE('Power BI'!I9)*86400 -> 15 | AI36: =INT(AG36/60) & "m" & IF(MOD(AG36,60)=0,""," " & TEXT(MOD(AG36,60),"00") & "s") -> 6m 30s
W37: myCCA | X37: =SUM(AE4:AE7,AE9:AE10) -> 88.798764 | Y37: =AE37 -> 180 | Z37: =SUM(Sheet2!D49) -> 320 | AA37: =AG37 -> 419 | AB37: ='Power BI'!C12 -> 0.80650339 | AC37: =TIMEVALUE('Power BI'!D12)*86400 -> 18 | AD37: ='Power BI'!E12 -> 0.034 | AE37: ='Power BI'!F12 -> 180 | AF37: ='Power BI'!G12 -> 172 | AG37: =TIMEVALUE('Power BI'!H12)*86400 -> 419 | AH37: =TIMEVALUE('Power BI'!I12)*86400 -> 19 | AI37: =INT(AG37/60) & "m" & IF(MOD(AG37,60)=0,""," " & TEXT(MOD(AG37,60),"00") & "s") -> 6m 59s
W38: Consumer | X38: =SUM(Y4:Y7,Y9:Y10) -> 200.63473 | Y38: =AE38 -> 283 | Z38: =SUM(Sheet2!J49) -> 390 | AA38: =AG38 -> 406 | AB38: ='Power BI'!C14 -> 0.96113074 | AC38: =TIMEVALUE('Power BI'!D14)*86400 -> 5 | AD38: ='Power BI'!E14 -> 0.008 | AE38: ='Power BI'!F14 -> 283 | AF38: ='Power BI'!G14 -> 281 | AG38: =TIMEVALUE('Power BI'!H14)*86400 -> 406 | AH38: =TIMEVALUE('Power BI'!I14)*86400 -> 6 | AI38: =INT(AG38/60) & "m" & IF(MOD(AG38,60)=0,""," " & TEXT(MOD(AG38,60),"00") & "s") -> 6m 46s
W39: Sales | X39: =SUM(Z24:Z27,Z29:Z30) -> 796.8489 | Y39: =AE39 -> 1137 | Z39: =SUM(Sheet2!B49) -> 420 | AA39: =AG39 -> 427 | AB39: ='Power BI'!C16 -> 0.92167834 | AC39: =TIMEVALUE('Power BI'!D16)*86400 -> 14 | AD39: ='Power BI'!E16 -> 0.004 | AE39: ='Power BI'!F16 -> 1137 | AF39: ='Power BI'!G16 -> 1132 | AG39: =TIMEVALUE('Power BI'!H16)*86400 -> 427 | AH39: =TIMEVALUE('Power BI'!I16)*86400 -> 14 | AI39: =INT(AG39/60) & "m" & IF(MOD(AG39,60)=0,""," " & TEXT(MOD(AG39,60),"00") & "s") -> 7m 07s
W40: New Business | X40: =SUM(Y24:Y27,Y29:Y30) -> 62.659999 | Y40: =AE40 -> 74 | Z40: =SUM(Sheet2!C49) -> 600 | AA40: =AG40 -> 951 | AB40: ='Power BI'!C18 -> 0.85135135 | AC40: =TIMEVALUE('Power BI'!D18)*86400 -> 15 | AD40: ='Power BI'!E18 -> 0.028 | AE40: ='Power BI'!F18 -> 74 | AF40: ='Power BI'!G18 -> 72 | AG40: =TIMEVALUE('Power BI'!H18)*86400 -> 951 | AH40: =TIMEVALUE('Power BI'!I18)*86400 -> 20 | AI40: =INT(AG40/60) & "m" & IF(MOD(AG40,60)=0,""," " & TEXT(MOD(AG40,60),"00") & "s") -> 15m 51s
W41: Grinders | X41: =SUM(X24:X27,X29:X30) -> 53.07274 | Y41: =AE41 -> 72 | Z41: =SUM(Sheet2!E49:H49)/4 -> 445 | AA41: =AG41 -> 433 | AB41: ='Power BI'!C20 -> 0.86111111 | AC41: =TIMEVALUE('Power BI'!D20)*86400 -> 21 | AD41: ='Power BI'!E20 -> 0.014 | AE41: ='Power BI'!F20 -> 72 | AF41: ='Power BI'!G20 -> 71 | AG41: =TIMEVALUE('Power BI'!H20)*86400 -> 433 | AH41: =TIMEVALUE('Power BI'!I20)*86400 -> 24 | AI41: =INT(AG41/60) & "m" & IF(MOD(AG41,60)=0,""," " & TEXT(MOD(AG41,60),"00") & "s") -> 7m 13s
W46: Queue | Y46: Change
W47: Equipment | Y47: =(Y34-X34)/X34 -> 0.18671434 | AA47: =(AA34-Z34)/Z34 -> 0.22352941
...

Sheet Power BI
A1: Qeueue_groupings | B1: Queue (PK) | C1: SL | D1: ASA | E1: Abandoned No Short % | F1: Offer | G1: Answered | H1: AHT | I1: Avg Wait | Q1: Date | R1: SL | S1: ASA | T1: Abandoned No Short % | U1: Offer | V1: Answered | W1: AHT | X1: Avg Wait | Y1: Day
A2: Equipment | B2: Total | C2: 0.83799405 | D2: 0:00:19 | E2: 0.046 | F2: 1816 | G2: 1725 | H2: 0:06:56 | I2: 0:00:26 | Q2: 46123 | R2: 0.74 | S2: 0.0002662037 | T2: 0.12 | U2: 240 | V2: 209 | W2: 0.0045601852 | X2: 0.00048611111 | Y2: =WEEKDAY(Q2) -> 7
A3: Equipment | B3: EQS_Allocators_AU | C3: 0.71666667 | D3: 0:00:22 | E3: 0.116 | F3: 26 | G3: 21 | H3: 0:08:29 | I3: 0:00:31 | Q3: 46124 | R3: 0.87 | S3: 0.00015046296 | T3: 0.03 | U3: 183 | V3: 175 | W3: 0.0046064815 | X3: 0.00017361111 | Y3: =WEEKDAY(Q3) -> 1
A4: Equipment | B4: Tech_AU | C4: 0.85218194 | D4: 0:00:18 | E4: 0.036 | F4: 1028 | G4: 987 | H4: 0:06:49 | I4: 0:00:23 | Q4: 46125 | R4: 0.83 | S4: 0.00021990741 | T4: 0.03 | U4: 1296 | V4: 1257 | W4: 0.0051967593 | X4: 0.00024305556 | Y4: =WEEKDAY(Q4) -> 2
A5: Equipment | B5: Vending_AU | C5: 0.82274785 | D5: 0:00:17 | E5: 0.058 | F5: 762 | G5: 717 | H5: 0:07:03 | I5: 0:00:25 | Q5: 46126 | R5: 0.92 | S5: 6.9444444e-05 | T5: 0.02 | U5: 1069 | V5: 1050 | W5: 0.0052662037 | X5: 8.1018519e-05 | Y5: =WEEKDAY(Q5) -> 3
A6: Delivery | B6: Total | C6: 0.88415373 | D6: 0:00:11 | E6: 0.03 | F6: 1233 | G6: 1194 | H6: 0:08:40 | I6: 0:00:17 | Q6: 46127 | R6: 0.9 | S6: 0.00027777778 | T6: 0.02 | U6: 1053 | V6: 1029 | W6: 0.0050578704 | X6: 0.00028935185 | Y6: =WEEKDAY(Q6) -> 4
A7: Delivery | B7: Delivery_2_AU | C7: 0.89839572 | D7: 0:00:09 | E7: 0.022 | F7: 374 | G7: 366 | H7: 0:09:51 | I7: 0:00:15 | Q7: 46128 | R7: 0.91 | S7: 8.1018519e-05 | T7: 0.01 | U7: 1049 | V7: 1033 | W7: 0.0051967593 | X7: 0.00011574074 | Y7: =WEEKDAY(Q7) -> 5
A8: Delivery | B8: Delivery_AU | C8: 0.87793118 | D8: 0:00:13 | E8: 0.033 | F8: 859 | G8: 828 | H8: 0:08:09 | I8: 0:00:18 | Q8: 46129 | R8: 0.88 | S8: 0.00024305556 | T8: 0.03 | U8: 883 | V8: 859 | W8: 0.0050925926 | X8: 0.0002662037 | Y8: =WEEKDAY(Q8) -> 6
A9: Credit | B9: Total | C9: 0.89605796 | D9: 0:00:14 | E9: 0.011 | F9: 978 | G9: 965 | H9: 0:06:30 | I9: 0:00:15 | Q9: Total | R9: 0.88 | S9: 0.00018518519 | T9: 0.03 | U9: 5773 | V9: 5612 | W9: 0.0051273148 | X9: 0.00023148148
A10: Credit | B10: Credit Enquiries_2_AU | C10: 0.80951148 | D10: 0:00:21 | E10: 0.018 | F10: 283 | G10: 276 | H10: 0:06:29 | I10: 0:00:22
A11: Credit | B11: Credit Enquiries_AU | C11: 0.93110055 | D11: 0:00:07 | E11: 0.008 | F11: 695 | G11: 689 | H11: 0:06:30 | I11: 0:00:07
A12: myCCA_AU | B12: Total | C12: 0.80650339 | D12: 0:00:18 | E12: 0.034 | F12: 180 | G12: 172 | H12: 0:06:59 | I12: 0:00:19
A13: myCCA_AU | B13: myCCA_AU | C13: 0.80650339 | D13: 0:00:18 | E13: 0.034 | F13: 180 | G13: 172 | H13: 0:06:59 | I13: 0:00:19
A14: Consumer Services_AU | B14: Total | C14: 0.96113074 | D14: 0:00:05 | E14: 0.008 | F14: 283 | G14: 281 | H14: 0:06:46 | I14: 0:00:06
A15: Consumer Services_AU | B15: Consumer Services_AU | C15: 0.96113074 | D15: 0:00:05 | E15: 0.008 | F15: 283 | G15: 281 | H15: 0:06:46 | I15: 0:00:06
A16: Sales_AU | B16: Total | C16: 0.92167834 | D16: 0:00:14 | E16: 0.004 | F16: 1137 | G16: 1132 | H16: 0:07:07 | I16: 0:00:14
A17: Sales_AU | B17: Sales_AU | C17: 0.92167834 | D17: 0:00:14 | E17: 0.004 | F17: 1137 | G17: 1132 | H17: 0:07:07 | I17: 0:00:14
A18: New_Business_AU | B18: Total | C18: 0.85135135 | D18: 0:00:15 | E18: 0.028 | F18: 74 | G18: 72 | H18: 0:15:51 | I18: 0:00:20
A19: New_Business_AU | B19: New_Business_AU | C19: 0.85135135 | D19: 0:00:15 | E19: 0.028 | F19: 74 | G19: 72 | H19: 0:15:51 | I19: 0:00:20 | Q19: Qeueue_groupings | R19: SL | S19: ASA | T19: Abandoned No Short % | U19: Offer | V19: Answered | W19: AHT | X19: Avg Wait
A20: Grinders | B20: Total | C20: 0.86111111 | D20: 0:00:21 | E20: 0.014 | F20: 72 | G20: 71 | H20: 0:07:13 | I20: 0:00:24 | Q20: AU_NSC_Live_Agent_Consultant | R20: 0.94378194 | S20: 0:00:06 | U20: 592 | V20: 587 | W20: 0:12:40 | X20: 0:00:06
A21: Grinders | B21: Grinders_Caffitaly_AU | C21: 0.83333333 | D21: 0:00:54 | F21: 6 | G21: 6 | H21: 0:06:44 | I21: 0:00:54 | Q21: Total | R21: 0.94378194 | S21: 0:00:06 | U21: 592 | V21: 587 | W21: 0:12:40 | X21: 0:00:06
A22: Grinders | B22: Grinders_Rep_AU | C22: 0.9375 | D22: 0:00:03 | F22: 16 | G22: 16 | H22: 0:09:57 | I22: 0:00:03
A23: Grinders | B23: Grinders_Sales_AU | C23: 0.89655172 | D23: 0:00:19 | F23: 29 | G23: 29 | H23: 0:06:07 | I23: 0:00:19 | Q23: Applied filters: Media Type is Chat SL% is not blank Date is on or after 4/4/2026 and is before 4/9/2026 Column is ISS or NSC Column1 is Aus or ISS AU Queue is not (Blank), Cust/Consumer Relations, EQS Scheduling NSC, NSC - Inbound Credit, NSC - Order & Delivery, NSC - Order Maintenance, NSC Campaign, NSC Online - Allocation Requests, NSC Online - CCSP, NSC Online - Consumer, NSC Online - Digital Support, NSC Online - E-Business, NSC Online - Email Orders, NSC Online - EQS, NSC Online - Key Account, NSC Online - MADE, NSC Online - New Business, NSC Online - SOCO, NSC Online - Support, NZ NCC Cafe-Direct General, NZ NCC CIC, NZ NCC General, NZ NCC GROW COKE, NZ NCC Licensed, NZ NCC Live Message, NZ NCC MyCCA, NZ NCC Operator, NZ NCC Rep, NZ NCC SEC Support, RY4T2B, RY4T2C, RY4T2D, RY4T3D, RY4T3E, RY4T3F, RY4T4B, RY4T5B, RY4T5C, or RY4T5D Team does not contain 'Terminated'
A24: Grinders | B24: Grinders_Tech_AU | C24: 0.76190476 | D24: 0:00:23 | E24: 0.048 | F24: 21 | G24: 20 | H24: 0:06:48 | I24: 0:00:32
A26: Total | C26: 0.87975035 | D26: 0:00:16 | E26: 0.025 | F26: 5773 | G26: 5612 | H26: 0:07:23 | I26: 0:00:20
A30: Applied filters: Media Type is Voice SL% is not blank Media Type is voice Date is on or after 4/4/2026 and is before 4/9/2026 Column is ISS or NSC Column1 is Aus or ISS AU Queue is not (Blank), Cust/Consumer Relations, EQS Scheduling NSC, N&K - Customer Support, N&K Online - Customer Support, New Business Campaign, NSC - Inbound Credit, NSC - Order & Delivery, NSC - Order Maintenance, NSC Campaign, NSC Online - Allocation Requests, NSC Online - CCSP, NSC Online - Consumer, NSC Online - Digital Support, NSC Online - E-Business, NSC Online - Email Orders, NSC Online - EQS, NSC Online - Key Account, NSC Online - MADE, NSC Online - New Business, NSC Online - SOCO, NSC Online - Support, NZ NCC Cafe-Direct General, NZ NCC CIC, NZ NCC General, NZ NCC GROW COKE, NZ NCC Licensed, NZ NCC Live Message, NZ NCC MyCCA, NZ NCC Operator, NZ NCC Rep, NZ NCC SEC Support, RY4T2B, RY4T2C, RY4T2D, RY4T3D, RY4T3E, RY4T3F, RY4T4B, RY4T5B, RY4T5C, or RY4T5D Team does not contain 'Terminated'
B49: Consumer Services_AU | C49: Total | D49: 0.97 | E49: 4.6296296e-05 | G49: 224 | H49: 224 | I49: 0.0047106481 | J49: 4.6296296e-05
C50: Consumer Services_AU | D50: 0.97 | E50: 4.6296296e-05 | G50: 224 | H50: 224 | I50: 0.0047106481 | J50: 4.6296296e-05
B51: Credit | C51: Total | D51: 0.88 | E51: 0.00018518519 | F51: 0.01 | G51: 838 | H51: 825 | I51: 0.0045138889 | J51: 0.00018518519
C52: Credit Enquiries_2_AU | D52: 0.8 | E52: 0.0002662037 | F52: 0.02 | G52: 239 | H52: 232 | I52: 0.0045717593 | J52: 0.00027777778
C53: Credit Enquiries_AU | D53: 0.92 | E53: 9.2592593e-05 | F53: 0.01 | G53: 599 | H53: 593 | I53: 0.0044907407 | J53: 9.2592593e-05
B54: Delivery | C54: Total | D54: 0.88 | E54: 0.00011574074 | F54: 0.03 | G54: 1066 | H54: 1032 | I54: 0.0059606481 | J54: 0.00019675926
C55: Delivery_2_AU | D55: 0.9 | E55: 9.2592593e-05 | F55: 0.02 | G55: 323 | H55: 317 | I55: 0.0067824074 | J55: 0.00017361111
C56: Delivery_AU | D56: 0.88 | E56: 0.00013888889 | F56: 0.03 | G56: 743 | H56: 715 | I56: 0.0056018519 | J56: 0.00021990741
B57: Equipment | C57: Total | D57: 0.84 | E57: 0.00017361111 | F57: 0.05 | G57: 1524 | H57: 1449 | I57: 0.0047916667 | J57: 0.0002662037
C58: EQS_Allocators_AU | D58: 0.71 | E58: 0.00012731481 | F58: 0.14 | G58: 22 | H58: 17 | I58: 0.0037615741 | J58: 0.00025462963
C59: Tech_AU | D59: 0.86 | E59: 0.00019675926 | F59: 0.04 | G59: 860 | H59: 826 | I59: 0.0047685185 | J59: 0.00025462963
C60: Vending_AU | D60: 0.83 | E60: 0.00019675926 | F60: 0.06 | G60: 642 | H60: 606 | I60: 0.0048726852 | J60: 0.00028935185
B61: Grinders | C61: Total | D61: 0.89 | E61: 0.00023148148 | F61: 0.02 | G61: 55 | H61: 54 | I61: 0.0056018519 | J61: 0.0002662037
C62: Grinders_Caffitaly_AU | D62: 0.8 | E62: 0.0009375 | G62: 5 | H62: 5 | I62: 0.0052430556 | J62: 0.0009375
...

Sheet Working File (2)
C2: Phone - Inbound | E2: SLA | G2: ASA | I2: Abandoned | K2: Volume vs FCST | N2: AHT vs FCST | Q2: Owner | R2: Queues | W2: Column Labels
C3: Services | V3: Day | W3: NSC_Allocators_PG | X3: NSC_ConsumerRelations_PG | Y3: NSC_CreditEnquiries_2_PG | Z3: NSC_CreditEnquiries_PG | AA3: NSC_Delivery_2_PG | AB3: NSC_Delivery_PG | AC3: NSC_LiveAgent_PG | AD3: NSC_myCCA_PG | AE3: NSC_Tech_PG | AF3: NSC_Vending_PG | AG3: Grand Total
C4: Equipment | D4: =AA34 -> 0.83799405 | E4: =AA34 -> 0.83799405 | F4: =AB34 -> 19 | G4: =AB34&"s" -> 19s | H4: =I4 -> 0.046 | I4: =AC34 -> 0.046 | J4: =X47 -> 0.18671434 | K4: =J4 -> 0.18671434 | L4: =X47 -> 0.18671434 | M4: =X34 -> 1816 | N4: =Z47 -> 0.22352941 | O4: =Z47 -> 0.22352941 | P4: =AH34 -> 6m 56s | Q4: ISS | R4: Tech_AU, Vending_AU, EQS Allocators_AU | V4: Monday | W4: 3.9533451 | X4: 54.365461 | Y4: 51.111345 | Z4: 102.10043 | AA4: 53.21194 | AB4: 226.66197 | AC4: 121.79202 | AD4: 23.900315 | AE4: 169.89482 | AF4: 130.2818 | AG4: 937.27345
C5: Delivery | D5: =AA35 -> 0.88415373 | E5: =AA35 -> 0.88415373 | F5: =AB35 -> 11 | G5: =AB35&"s" -> 11s | H5: =I5 -> 0.03 | I5: =AC35 -> 0.03 | J5: =X48 -> 0.046903526 | K5: =J5 -> 0.046903526 | L5: =X48 -> 0.046903526 | M5: =X35 -> 1233 | N5: =Z48 -> 0.23809524 | O5: =Z48 -> 0.23809524 | P5: =AH35 -> 8m 40s | Q5: AU | R5: Delivery_AU, Delivery 2_AU | V5: Tuesday | W5: 3.9537504 | X5: 47.893581 | Y5: 40.888887 | Z5: 86.257258 | AA5: 66.515118 | AB5: 218.14861 | AC5: 109.74224 | AD5: 20.22345 | AE5: 159.59275 | AF5: 141.9382 | AG5: 895.15385
C6: Credit | D6: =AA36 -> 0.89605796 | E6: =AA36 -> 0.89605796 | F6: =AB36 -> 14 | G6: =AB36&"s" -> 14s | H6: =I6 -> 0.011 | I6: =AC36 -> 0.011 | J6: =X49 -> 0.87346335 | K6: =J6 -> 0.87346335 | L6: =X49 -> 0.87346335 | M6: =X36 -> 978 | N6: =Z49 -> -0.23529412 | O6: =Z49 -> -0.23529412 | P6: =AH36 -> 6m 30s | Q6: ISS | R6: Credit Enquiries_AU, Credit Enquiries_2_AU | V6: Wednesday | W6: 3.953264 | X6: 50.482106 | Y6: 36.629292 | Z6: 84.555578 | AA6: 61.963978 | AB6: 212.82728 | AC6: 108.02028 | AD6: 20.590794 | AE6: 151.388 | AF6: 140.56619 | AG6: 870.97676
C7: myCCA | D7: =AA37 -> 0.80650339 | E7: =AA37 -> 0.80650339 | F7: =AB37 -> 18 | G7: =AB37&"s" -> 18s | H7: =I7 -> 0.034 | I7: =AC37 -> 0.034 | J7: =X50 -> 1.0270552 | K7: =J7 -> 1.0270552 | L7: =X50 -> 1.0270552 | M7: =X37 -> 180 | N7: =Z50 -> 0.309375 | O7: =Z50 -> 0.309375 | P7: =AH37 -> 6m 59s | Q7: AU | R7: myCCA_AU | V7: Thursday | W7: 4.3490201 | X7: 47.893581 | Y7: 40.037062 | Z7: 80.271928 | AA7: 61.613814 | AB7: 215.48832 | AC7: 101.99573 | AD7: 16.914293 | AE7: 150.6476 | AF7: 138.50995 | AG7: 857.72129
C8: Consumer | D8: =AA38 -> 0.96113074 | E8: =AA38 -> 0.96113074 | F8: =AB38 -> 5 | G8: =AB38&"s" -> 5s | H8: =I8 -> 0.008 | I8: =AC38 -> 0.008 | J8: =X51 -> 0.4105235 | K8: =J8 -> 0.4105235 | L8: =X51 -> 0.4105235 | M8: =X38 -> 283 | N8: =Z51 -> 0.041025641 | O8: =Z51 -> 0.041025641 | P8: =AH38 -> 6m 46s | Q8: AU | R8: Consumer Services_AU | V8: Friday | W8: 3.1628868 | X8: 54.365272 | Y8: 38.333414 | Z8: 74.638758 | AA8: 51.111568 | AB8: 226.12948 | AC8: 92.097753 | AD8: 18.201236 | AE8: 141.39423 | AF8: 126.16728 | AG8: 825.60188
C9: Sales | V9: Saturday | W9: 7.9066902 | Z9: 0.05868112 | AA9: 0.23349418 | AB9: 35.205669 | AC9: 22.378638 | AD9: 3.4930474 | AE9: 90.313904 | AF9: 82.282758 | AG9: 241.87288
C10: Sales | D10: =AA39 -> 0.92167834 | E10: =AA39 -> 0.92167834 | F10: =AB39 -> 14 | G10: =AB39&"s" -> 14s | H10: =I10 -> 0.004 | I10: =AC39 -> 0.004 | J10: =X52 -> 0.42687026 | K10: =J10 -> 0.42687026 | L10: =X52 -> 0.42687026 | M10: =X39 -> 1137 | N10: =Z52 -> 0.016666667 | O10: =Z52 -> 0.016666667 | P10: =AH39 -> 7m 07s | Q10: ISS | R10: Sales AU | V10: Sunday | W10: 6.7210433 | Z10: 0.11736224 | AA10: 0.35008765 | AB10: 25.538663 | AC10: 27.97334 | AD10: 3.6768652 | AE10: 74.768693 | AF10: 69.253827 | AG10: 208.39988
C11: New Business | D11: =AA40 -> 0.85135135 | E11: =AA40 -> 0.85135135 | F11: =AB40 -> 15 | G11: =AB40&"s" -> 15s | H11: =I11 -> 0.028 | I11: =AC40 -> 0.028 | J11: =X53 -> 0.18097673 | K11: =J11 -> 0.18097673 | L11: =X53 -> 0.18097673 | M11: =X40 -> 74 | N11: =Z53 -> 0.585 | O11: =Z53 -> 0.585 | P11: =AH40 -> 15m 51s | Q11: ISS | R11: New_Business_AU | W11: 34 | X11: 255 | Y11: 207 | Z11: 428 | AA11: 295 | AB11: 1160 | AC11: 584 | AD11: 107 | AE11: 938 | AF11: 829 | AG11: 4837
C12: Grinders | D12: =AA41 -> 0.86111111 | E12: =AA41 -> 0.86111111 | F12: =AB41 -> 21 | G12: =AB41&"s" -> 21s | H12: =I12 -> 0.014 | I12: =AC41 -> 0.014 | J12: =X54 -> 0.35662865 | K12: =J12 -> 0.35662865 | L12: =X54 -> 0.35662865 | M12: =X41 -> 72 | N12: =Z54 -> -0.026966292 | O12: =Z54 -> -0.026966292 | P12: =AH41 -> 7m 13s | Q12: ISS & AU | R12: Sales_AU, Tech_AU, Rep_AU, Credits_AU, Caffitaly_AU
V13: Day | W13: NSC_Email_Consumer_PG | X13: NSC_Email_DigitalSupport_PG | Y13: NSC_Email_Inbound_Credit_PG | Z13: NSC_Email_Online_EQS_PG | AA13: NSC_Email_Order&Delivery_PG | AB13: NSC_Email_OrderMaintenance_PG | AC13: Grand Total
V14: Monday | W14: 136.51264 | X14: 50.570381 | Y14: 228.39376 | Z14: 46.811317 | AA14: 24.506059 | AB14: 50.368064 | AC14: 537.16221
V15: Tuesday | W15: 156.88915 | X15: 39.507094 | Y15: 166.52873 | Z15: 43.854763 | AA15: 24.506059 | AB15: 57.774478 | AC15: 489.06028
V16: Wednesday | W16: 179.30102 | X16: 42.668328 | Y16: 157.96868 | Z16: 38.927382 | AA16: 32.677868 | AB16: 60.738683 | AC16: 512.28196
V17: Thursday | W17: 167.0739 | X17: 42.66801 | Y17: 153.68919 | Z17: 37.449778 | AA17: 46.293733 | AB17: 59.25658 | AC17: 506.43119
V18: Friday | W18: 132.4381 | X18: 38.19064 | Y18: 143.57243 | Z18: 41.883831 | AA18: 49.016281 | AB18: 50.368649 | AC18: 455.46992
V19: Saturday | W19: 107.98673 | X19: 15.802045 | Y19: 8.1709608 | Z19: 14.29037 | AB19: 0.49354625 | AC19: 146.74365
V20: Sunday | W20: 97.798471 | X20: 16.593503 | Y20: 18.676248 | Z20: 14.782559 | AC20: 147.85078
W21: 978 | X21: 246 | Y21: 877 | Z21: 238 | AA21: 177 | AB21: 279 | AC21: 2795
V23: Day | W23: AU_Grinders_PG | X23: NSC_NewBusiness_PG | Y23: NSC_Sales_PG | Z23: Grand Total
V24: Monday | W24: 14.788205 | X24: 18.31809 | Y24: 240.21314 | Z24: 273.31943
V25: Tuesday | W25: 12.323323 | X25: 16.42836 | Y25: 193.94057 | Z25: 222.69226
V26: Wednesday | W26: 10.679974 | X26: 13.956774 | Y26: 166.61646 | Z26: 191.25321
V27: Thursday | W27: 11.501848 | X27: 13.956774 | Y27: 167.86426 | Z27: 193.32288
V28: Friday | W28: 9.9272596 | X28: 11.340001 | Y28: 167.1511 | Z28: 188.41836
V29: Saturday | W29: 2.1360975 | Y29: 13.186306 | Z29: 15.322403
V30: Sunday | W30: 1.6432925 | Y30: 15.028169 | Z30: 16.671461
W31: 63 | X31: 74 | Y31: 964 | Z31: 1101
V33: FCST Volume | W33: Forecasted Volume | X33: Actual Volume | Y33: Forecasted AHT | Z33: Actual AHT | AA33: SL | AB33: ASA | AC33: Abandoned No Short % | AD33: Offer | AE33: Answered | AF33: AHT | AG33: Avg Wait
V34: Equipment | W34: =SUM(W4:W7,W9:W10,AE4:AE7,AE9:AE10,AF4:AF7,AF9:AF10) -> 1530.2756 | X34: =AD34 -> 1816 | Y34: =SUM(Sheet2!K49,Sheet2!L49,Sheet2!Q49)/3 -> 340 | Z34: =AF34 -> 416 | AA34: ='Power BI'!C2 -> 0.83799405 | AB34: =TIMEVALUE('Power BI'!D2)*86400 -> 19 | AC34: ='Power BI'!E2 -> 0.046 | AD34: ='Power BI'!F2 -> 1816 | AE34: ='Power BI'!G2 -> 1725 | AF34: =TIMEVALUE('Power BI'!H2) * 86400 -> 416 | AG34: =TIMEVALUE('Power BI'!I2)*86400 -> 26 | AH34: =INT(AF34/60) & "m" & IF(MOD(AF34,60)=0,""," " & TEXT(MOD(AF34,60),"00") & "s") -> 6m 56s
V35: Delivery | W35: =SUM(AA4:AA7,AA9:AA10,AB4:AB7,AB9:AB10) -> 1177.759 | X35: =AD35 -> 1233 | Y35: =SUM(Sheet2!M49,Sheet2!N49)/2 -> 420 | Z35: =AF35 -> 520 | AA35: ='Power BI'!C6 -> 0.88415373 | AB35: =TIMEVALUE('Power BI'!D6)*86400 -> 11 | AC35: ='Power BI'!E6 -> 0.03 | AD35: ='Power BI'!F6 -> 1233 | AE35: ='Power BI'!G6 -> 1194 | AF35: =TIMEVALUE('Power BI'!H6)*86400 -> 520 | AG35: =TIMEVALUE('Power BI'!I6)*86400 -> 17 | AH35: =INT(AF35/60) & "m" & IF(MOD(AF35,60)=0,""," " & TEXT(MOD(AF35,60),"00") & "s") -> 8m 40s
V36: Credit | W36: =SUM(Z4:Z7,Z9:Z10,Y4:Y7,Y9:Y10) -> 522.02783 | X36: =AD36 -> 978 | Y36: =SUM(Sheet2!O49,Sheet2!P49)/2 -> 510 | Z36: =AF36 -> 390 | AA36: ='Power BI'!C9 -> 0.89605796 | AB36: =TIMEVALUE('Power BI'!D9)*86400 -> 14 | AC36: ='Power BI'!E9 -> 0.011 | AD36: ='Power BI'!F9 -> 978 | AE36: ='Power BI'!G9 -> 965 | AF36: =TIMEVALUE('Power BI'!H9)*86400 -> 390 | AG36: =TIMEVALUE('Power BI'!I9)*86400 -> 15 | AH36: =INT(AF36/60) & "m" & IF(MOD(AF36,60)=0,""," " & TEXT(MOD(AF36,60),"00") & "s") -> 6m 30s
V37: myCCA | W37: =SUM(AD4:AD7,AD9:AD10) -> 88.798764 | X37: =AD37 -> 180 | Y37: =SUM(Sheet2!D49) -> 320 | Z37: =AF37 -> 419 | AA37: ='Power BI'!C12 -> 0.80650339 | AB37: =TIMEVALUE('Power BI'!D12)*86400 -> 18 | AC37: ='Power BI'!E12 -> 0.034 | AD37: ='Power BI'!F12 -> 180 | AE37: ='Power BI'!G12 -> 172 | AF37: =TIMEVALUE('Power BI'!H12)*86400 -> 419 | AG37: =TIMEVALUE('Power BI'!I12)*86400 -> 19 | AH37: =INT(AF37/60) & "m" & IF(MOD(AF37,60)=0,""," " & TEXT(MOD(AF37,60),"00") & "s") -> 6m 59s
V38: Consumer | W38: =SUM(X4:X7,X9:X10) -> 200.63473 | X38: =AD38 -> 283 | Y38: =SUM(Sheet2!J49) -> 390 | Z38: =AF38 -> 406 | AA38: ='Power BI'!C14 -> 0.96113074 | AB38: =TIMEVALUE('Power BI'!D14)*86400 -> 5 | AC38: ='Power BI'!E14 -> 0.008 | AD38: ='Power BI'!F14 -> 283 | AE38: ='Power BI'!G14 -> 281 | AF38: =TIMEVALUE('Power BI'!H14)*86400 -> 406 | AG38: =TIMEVALUE('Power BI'!I14)*86400 -> 6 | AH38: =INT(AF38/60) & "m" & IF(MOD(AF38,60)=0,""," " & TEXT(MOD(AF38,60),"00") & "s") -> 6m 46s
V39: Sales | W39: =SUM(Y24:Y27,Y29:Y30) -> 796.8489 | X39: =AD39 -> 1137 | Y39: =SUM(Sheet2!B49) -> 420 | Z39: =AF39 -> 427 | AA39: ='Power BI'!C16 -> 0.92167834 | AB39: =TIMEVALUE('Power BI'!D16)*86400 -> 14 | AC39: ='Power BI'!E16 -> 0.004 | AD39: ='Power BI'!F16 -> 1137 | AE39: ='Power BI'!G16 -> 1132 | AF39: =TIMEVALUE('Power BI'!H16)*86400 -> 427 | AG39: =TIMEVALUE('Power BI'!I16)*86400 -> 14 | AH39: =INT(AF39/60) & "m" & IF(MOD(AF39,60)=0,""," " & TEXT(MOD(AF39,60),"00") & "s") -> 7m 07s
V40: New Business | W40: =SUM(X24:X27,X29:X30) -> 62.659999 | X40: =AD40 -> 74 | Y40: =SUM(Sheet2!C49) -> 600 | Z40: =AF40 -> 951 | AA40: ='Power BI'!C18 -> 0.85135135 | AB40: =TIMEVALUE('Power BI'!D18)*86400 -> 15 | AC40: ='Power BI'!E18 -> 0.028 | AD40: ='Power BI'!F18 -> 74 | AE40: ='Power BI'!G18 -> 72 | AF40: =TIMEVALUE('Power BI'!H18)*86400 -> 951 | AG40: =TIMEVALUE('Power BI'!I18)*86400 -> 20 | AH40: =INT(AF40/60) & "m" & IF(MOD(AF40,60)=0,""," " & TEXT(MOD(AF40,60),"00") & "s") -> 15m 51s
V41: Grinders | W41: =SUM(W24:W27,W29:W30) -> 53.07274 | X41: =AD41 -> 72 | Y41: =SUM(Sheet2!E49:H49)/4 -> 445 | Z41: =AF41 -> 433 | AA41: ='Power BI'!C20 -> 0.86111111 | AB41: =TIMEVALUE('Power BI'!D20)*86400 -> 21 | AC41: ='Power BI'!E20 -> 0.014 | AD41: ='Power BI'!F20 -> 72 | AE41: ='Power BI'!G20 -> 71 | AF41: =TIMEVALUE('Power BI'!H20)*86400 -> 433 | AG41: =TIMEVALUE('Power BI'!I20)*86400 -> 24 | AH41: =INT(AF41/60) & "m" & IF(MOD(AF41,60)=0,""," " & TEXT(MOD(AF41,60),"00") & "s") -> 7m 13s
V46: Queue | X46: Change
V47: Equipment | X47: =(X34-W34)/W34 -> 0.18671434 | Z47: =(Z34-Y34)/Y34 -> 0.22352941
...
